# 비동기함수의 에러처리

```js
try {
    setTimeout(() => throw new Error('Error!'), 1000)
} catch (e) {
    console.error('캐치한 에러', e)
}
```

- setTimeout 함수가 실행되고 그 결과가 콜백큐에 들어가는데 그 콜백큐의 함수가 실행될 때 에러가 나는거지 setTimeout이 에러가 나는게 아니라서 에러를 캐치못함



```js
try {
  setTimeout(() => {
    try {
      throw new Error('Error!')
    } catch (e) {
      console.error('캐치한 내부 에러', e)
    }
  }, 1000)
} catch (e) {
  console.error('캐치한 에러', e)
}
```

- 내부 에러를 캐치할려면 이렇게해야됨







# 스코프

선언식은 for, if문에서 블록스코프 형성x(블록 밖에서도 사용가능)

표현식은 for, if문 안에서만 사용 가능

```js
if(1) {
    function a() {
        console.log('123')
    }
}

a()
// 이건 잘 실행됨


if(1) {
    const a = () => {
        console.log('123')
    }
}

a()
// 이건 a is not defined 에러뜸

```





# 반복문 비동기처리

- 병렬처리

```js
const a = [1, 2, 3]

const wait = (t) => new Promise((res) => {setTimeout(() => {console.log('dd'); res()}, t)})

const fb = async () => {
    await Promise.all(a.map(async (n) => {
        await wait(n * 1000)
        return n + 1
    }))
    console.log('ff')
}

fb()
// dd
// dd
// dd
// ff
// 3초걸림
```

- 직렬처리

```js
const a = [1, 2, 3]

const wait = (t) => new Promise((res) => {setTimeout(() => {console.log('dd'); res()}, t)})

const fb = async () => {
    for (n of a) {
        await wait(n * 1000)
    }
    console.log('ff')
}

fb()
// dd
// dd
// dd
// ff
// 6초걸림
```

