# 비동기함수의 에러처리

```js
try {
    setTimeout(() => throw new Error('Error!'), 1000)
} catch (e) {
    console.error('캐치한 에러', e)
}
```

- setTimeout 함수가 실행되고 그 결과가 콜백큐에 들어가는데 그 콜백큐의 함수가 실행될 때 에러가 나는거지 setTimeout이 에러가 나는게 아니라서 에러를 캐치못함



```js
try {
  setTimeout(() => {
    try {
      throw new Error('Error!')
    } catch (e) {
      console.error('캐치한 내부 에러', e)
    }
  }, 1000)
} catch (e) {
  console.error('캐치한 에러', e)
}
```

- 내부 에러를 캐치할려면 이렇게해야됨